Workbook

Sheet Read Me
A1: Kerala private clinical establishments — postcard mail list
A3: Source | B3: Register of Clinical Establishments, Kerala State Council for Clinical Establishments (KSCCE), as on 01.08.2026
A4: Source files | B4: Clinical_Permanent_AUG2026 and Clinical_Provisional_AUG2026 (both downloaded from clinicalestablishments.kerala.gov.in)
A5: Built | B5: 20 September 2026
A7: What was done
A8: 1 | B8: Both registers combined: 19,134 rows.
A9: 2 | B9: Filtered to OWNERSHIP = PVT. This removes 6,393 government establishments (PHCs, CHCs, family health centres, district hospitals) which are not buyers.
A10: 3 | B10: The register jams clinic name, address, landline, mobile and email into a single cell. These were parsed into separate columns.
A11: 4 | B11: Duplicates removed where the same name appears at the same address in both registers (435 rows). Branches of the same chain at different addresses were KEPT — each is its own reception desk.
A12: 5 | B12: PIN codes recovered. Only 10% of rows carried one. Post-office and place names in each address were matched against the India Post directory, restricted to the establishment's own district. Coverage is now 65%.
A14: How to use it
B15: Go to the "Mail List" tab. Use the filter arrows on row 1.
B16: Filter District to your own district first. Filter Category to drop what you do not want — Laboratory, Diagnostic Imaging Centre and Multi Specialty Hospital are probably not your buyers; Health Centre/Clinics/Polyclinics, Dental and Day Care Centre are.
B17: Sort by PIN Confidence and post the High rows first.
B18: The "Address Block" column is ready to print as-is — it is already laid out as the lines of a postal address.
A20: PIN Confidence
A21: High | B21: The PIN was printed in the clinic's own registered address, or matched an explicit "<place> P.O" in it. Post these first.
A22: Medium | B22: No PIN given, but exactly one place name in the address matches a post office in that district. Reliable, but not the clinic's own wording.
A23: Low | B23: Several place names matched different post offices. The PIN shown is a guess. The card will usually still arrive on the district and place name — consider deleting the PIN rather than printing a wrong one.
A24: No PIN | B24: No match found. Still postable if the address names a place and a post office; India Post will sort it by hand, more slowly.
A26: Caveat | B26: The Act exempts establishments "offering only consultation services", so a doctor with nothing but a consulting room may not appear here at all.
A27: Caveat | B27: 112 rows carry a PIN that the India Post directory assigns to a neighbouring district. These came from the clinic's own address and were left as written — border post offices are classified inconsistently between the two sources.
A28: Caveat | B28: 19 rows have no usable street address at all — only a clinic name. They are marked Postable = No. Their phone and email still work.
A29: Note | B29: Every row also has a mobile number and an email address, both at 100% coverage. See the Mobile and Email columns.

Sheet Mail List
A1: Clinic Name | B1: Address | C1: District | D1: PIN | E1: PIN Confidence | F1: Address Block | G1: Category | H1: System of Medicine | I1: Registration | J1: Reg No | K1: Mobile | L1: Landline | M1: Email | N1: Postable
A2: Anaril Vaidyasala | B2: Anaril Vaidyasala , Thrikunnapuzha, 9 | C2: Alappuzha | E2: No PIN | F2: Anaril Vaidyasala Anaril Vaidyasala, Thrikunnapuzha, 9 Kerala, Alappuzha | G2: Any Other | H2: Ayurveda | I2: Provisional | J2: T32554AY6983, Period - 19-02-2024 To 18-08-2028 | K2: 9446918019 | M2: anarilvaidyasala@gmail.com | N2: Yes
A3: DISEASE HELPLINE CENTRE | B3: DISEASE HELPLINE CENTRE, AVALUKKUNNU.P.O, POONTHOPPU WARD, ALAPPUZHA, 688006 | C3: Alappuzha | D3: 688006 | E3: High | F3: DISEASE HELPLINE CENTRE DISEASE HELPLINE CENTRE, AVALUKKUNNU.P.O, POONTHOPPU WARD Kerala, Alappuzha - 688006 | G3: Any Other | H3: Modern Medicine | I3: Provisional | J3: T32554MM5499, Period - 06-02-2024 To 05-08-2028 | K3: 9447212439 | L3: 04772232039 | M3: drshaji.alpy@gmail.com | N3: Yes
A4: Incare Medical Centre and Research Institute | B4: Murugan Junction, Karukayil Ward, Avalookunnu P.O, Kalarikal | C4: Alappuzha | D4: 688006 | E4: High | F4: Incare Medical Centre and Research Institute Murugan Junction, Karukayil Ward, Avalookunnu P.O, Kalarikal Kerala, Alappuzha - 688006 | G4: Any Other | H4: Yoga and Naturopathy | I4: Provisional | J4: T32554YN0777, Period - 19-07-2023 To 18-07-2027 | K4: 9744491144 | L4: 08921883156 | M4: incaregroups@gmail.com | N4: Yes
A5: KIOT ORTHO AND FAMILY CLINIC | B5: Ground Floor, Thiruvonam Complex, Near Puthuvilapadi Jun, Oripuram, Chennithala P O, Mavelikara, Kerala | C5: Alappuzha | D5: 690105 | E5: High | F5: KIOT ORTHO AND FAMILY CLINIC Ground Floor, Thiruvonam Complex, Near Puthuvilapadi Jun, Oripuram, Chennithala P O, Mavelikara Kerala, Alappuzha - 690105 | G5: Any Other | H5: Modern Medicine | I5: Provisional | J5: T32554MM2909, Period - 23-01-2024 To 22-07-2028 | K5: 9395241066 | L5: 04792322368 | M5: mzontalh@gmail.com | N5: Yes
A6: MATHERY MEDICAL MISSION HOSPITAL THOTTAPPALLY | B6: MATHERY MEDICAL MISSION HOSPITAL , THOTTAPPALLY P.O ALAPPUZHA | C6: Alappuzha | D6: 688001 | E6: Medium | F6: MATHERY MEDICAL MISSION HOSPITAL THOTTAPPALLY MATHERY MEDICAL MISSION HOSPITAL, THOTTAPPALLY P.O Kerala, Alappuzha - 688001 | G6: Any Other | H6: Modern Medicine | I6: Provisional | J6: T32554MM4353, Period - 29-01-2024 To 28-07-2028 | K6: 9645806225 | L6: 04772296225 | M6: matherydrislah@gmail.com | N6: Yes
A7: P K M Clinic | B7: P K M Clinic , Valanjavazhi , Vandanam P O | C7: Alappuzha | E7: No PIN | F7: P K M Clinic P K M Clinic, Valanjavazhi, Vandanam P O Kerala, Alappuzha | G7: Any Other | H7: Modern Medicine | I7: Provisional | J7: T32554MM487, Period - 23-05-2023 To 22-11-2027 | K7: 9495162779 | L7: 04792413014 | M7: radhakrishnank9495@gmail.com | N7: Yes
A8: SMM HOSPITAL | B8: SMM HOSPITAL, NANGIARKULANGARA P.O, ALAPPUZHA | C8: Alappuzha | D8: 690513 | E8: High | F8: SMM HOSPITAL SMM HOSPITAL, NANGIARKULANGARA P.O Kerala, Alappuzha - 690513 | G8: Any Other | H8: Modern Medicine | I8: Provisional | J8: T32554MM4227, Period - 29-01-2024 To 28-07-2028 | K8: 9447040640 | L8: 04792412640 | M8: ksgopal12345@gmail.com | N8: Yes
A9: THE AROOR CLINIC | B9: Ground Floor AP 20 160a Kannikkatt Building Near St Augustine Church Aroor Bypass Aroor Alappuzha | C9: Alappuzha | D9: 688001 | E9: Low | F9: THE AROOR CLINIC Ground Floor AP 20 160a Kannikkatt Building Near St Augustine Church Aroor Bypass Aroor Kerala, Alappuzha - 688001 | G9: Any Other | H9: Modern Medicine | I9: Provisional | J9: T32554MM5583, Period - 06-02-2024 To 05-08-2028 | K9: 9895052501 | L9: 04782990224 | M9: thearoorclinic2022@gmail.com | N9: Yes
A10: AB SCANS & LABORATORY | B10: NEAR GOVT HOSPITAL, KAYAMKULAM | C10: Alappuzha | D10: 690502 | E10: Medium | F10: AB SCANS & LABORATORY NEAR GOVT HOSPITAL, KAYAMKULAM Kerala, Alappuzha - 690502 | G10: Both Laboratory and Diagnostic Imaging Centre | H10: Modern Medicine | I10: Provisional | J10: T32554MMBOTH00013, Period - 07-03-2020 To 06-09-2024 | K10: 9207037777 | L10: 04792445149 | M10: abscanskylm@gmail.com | N10: Yes
A11: ABHIRAMI LABORATORY | B11: Abhirami Laboratory, Muttel Jn., Kuttamperoor P.O, Mannar | C11: Alappuzha | D11: 689623 | E11: High | F11: ABHIRAMI LABORATORY Abhirami Laboratory, Muttel Jn., Kuttamperoor P.O, Mannar Kerala, Alappuzha - 689623 | G11: Both Laboratory and Diagnostic Imaging Centre | H11: Modern Medicine | I11: Provisional | J11: T32554MMBOTH00008, Period - 28-11-2019 To 27-05-2024 | K11: 9605617687 | M11: sreedhanya528@gmail.com | N11: Yes
A12: ASWINI CLINICAL LABORATORY | B12: VALIYAPARAMBIL OPPOSITE GOVT HOSPITAL MANNAR | C12: Alappuzha | E12: No PIN | F12: ASWINI CLINICAL LABORATORY VALIYAPARAMBIL OPPOSITE GOVT HOSPITAL MANNAR Kerala, Alappuzha | G12: Both Laboratory and Diagnostic Imaging Centre | H12: Modern Medicine | I12: Provisional | J12: T32554MMBOTH00004, Period - 02-10-2019 To 01-04-2024 | K12: 9746280148 | L12: 04792312712 | M12: reshmi.krshnn@gmail.com | N12: Yes
A13: AV DIAGNOSTIC CENTRE | B13: 301 , NEAR SB AUDITORIUM , VAZHIYAMPALAM , KARUVATTA PO , HARIPPAD | C13: Alappuzha | E13: No PIN | F13: AV DIAGNOSTIC CENTRE 301, NEAR SB AUDITORIUM, VAZHIYAMPALAM, KARUVATTA PO, HARIPPAD Kerala, Alappuzha | G13: Both Laboratory and Diagnostic Imaging Centre | H13: Modern Medicine | I13: Provisional | J13: T32554MM3031, Period - 24-01-2024 To 23-07-2028 | K13: 8139810493 | L13: 04792995393 | M13: avdcrec@gmail.com | N13: Yes
A14: BIOTECH LAB & SCANS | B14: SV MALL, NEAR PUTHIYIDOM TEMPLE, KAYAMKULAM | C14: Alappuzha | D14: 690502 | E14: Medium | F14: BIOTECH LAB & SCANS SV MALL, NEAR PUTHIYIDOM TEMPLE, KAYAMKULAM Kerala, Alappuzha - 690502 | G14: Both Laboratory and Diagnostic Imaging Centre | H14: Modern Medicine | I14: Provisional | J14: T32554MMBOTH00007, Period - 26-11-2019 To 25-05-2024 | K14: 7025341122 | M14: biotechlabkylm@gmail.com | N14: Yes
A15: BIOVISION INDIA SPECIALITY DIAGNOSTIC CENTRE | B15: AISWARYA PLAZA, GOVT. HOSPITAL JN., THAZHAKARA, MAVELIKARA | C15: Alappuzha | D15: 690102 | E15: Medium | F15: BIOVISION INDIA SPECIALITY DIAGNOSTIC CENTRE AISWARYA PLAZA, GOVT. HOSPITAL JN., THAZHAKARA, MAVELIKARA Kerala, Alappuzha - 690102 | G15: Both Laboratory and Diagnostic Imaging Centre | H15: Modern Medicine | I15: Permanent | J15: P32554MM2970, Period - 15-02-2025 To 14-02-2030 | K15: 9446300734 | L15: 04792340082 | M15: biovisionkra@gmail.com | N15: Yes
A16: Biovision India Speciality Diagnostic Centre | B16: KARUVELIL BUILDING, NEAR SOUTH INDIAN BANK, MANNAR | C16: Alappuzha | E16: No PIN | F16: Biovision India Speciality Diagnostic Centre KARUVELIL BUILDING, NEAR SOUTH INDIAN BANK, MANNAR Kerala, Alappuzha | G16: Both Laboratory and Diagnostic Imaging Centre | H16: Modern Medicine | I16: Provisional | J16: T32554MMBOTH00006, Period - 02-10-2019 To 01-04-2024 | K16: 9447360734 | M16: biovisionkra@gmail.com | N16: Yes
A17: CHETHANA JANAKEEYA LAB | B17: CHETHANA JANAKEEYA LAB , TDMC P.O , VANDANAM , ALAPPUZHA | C17: Alappuzha | D17: 688001 | E17: Medium | F17: CHETHANA JANAKEEYA LAB CHETHANA JANAKEEYA LAB, TDMC P.O, VANDANAM Kerala, Alappuzha - 688001 | G17: Both Laboratory and Diagnostic Imaging Centre | H17: Modern Medicine | I17: Provisional | J17: T32554MM933, Period - 06-09-2023 To 05-03-2028 | K17: 8593082277 | L17: 04772282277 | M17: chetanapalliative@gmail.com | N17: Yes
A18: CITY LABORATORY | B18: Y.M.C.A Building, Near Govt.Hospital, Chengannur | C18: Alappuzha | D18: 689121 | E18: Medium | F18: CITY LABORATORY Y.M.C.A Building, Near Govt.Hospital, Chengannur Kerala, Alappuzha - 689121 | G18: Both Laboratory and Diagnostic Imaging Centre | H18: Modern Medicine | I18: Provisional | J18: T32554MMBOTH00016, Period - 28-05-2020 To 27-11-2024 | K18: 9388599996 | M18: citylabcgn@gmail.com | N18: Yes
A19: Chacko Memorial Diagnostics | B19: Chacko Memorial Diagnostics, Near Govt. Hospital, Thazhakara | C19: Alappuzha | D19: 690102 | E19: Medium | F19: Chacko Memorial Diagnostics Chacko Memorial Diagnostics, Near Govt. Hospital, Thazhakara Kerala, Alappuzha - 690102 | G19: Both Laboratory and Diagnostic Imaging Centre | H19: Modern Medicine | I19: Provisional | J19: T32554MMBOTH00001, Period - 25-07-2019 To 24-01-2024 | K19: 9447006316 | L19: 04792303222 | M19: chackomemorial@gmail.com | N19: Yes
A20: DDRC AGILUS PATH LABS | B20: DDRC AGILUS PATHLABS , NEAR ALAPPUZHA GH , PALACE WARD | C20: Alappuzha | D20: 688001 | E20: Medium | F20: DDRC AGILUS PATH LABS DDRC AGILUS PATHLABS, NEAR ALAPPUZHA GH, PALACE WARD Kerala, Alappuzha - 688001 | G20: Both Laboratory and Diagnostic Imaging Centre | H20: Modern Medicine | I20: Permanent | J20: P32554MM4896, Period - 03-09-2025 To 03-09-2030 | K20: 9446508300 | L20: 09446508300 | M20: sheela.benny@agilus.in | N20: Yes
A21: DDRC AGILUS PATHLABS LIMITED | B21: DDRC AGILUS PATHLABS LIMITED, GROUND FLOOR NEAR IRON BRIDGE, CHERTHALA | C21: Alappuzha | D21: 688524 | E21: Medium | F21: DDRC AGILUS PATHLABS LIMITED DDRC AGILUS PATHLABS LIMITED, GROUND FLOOR NEAR IRON BRIDGE, CHERTHALA Kerala, Alappuzha - 688524 | G21: Both Laboratory and Diagnostic Imaging Centre | H21: Modern Medicine | I21: Permanent | J21: P32554MM0686, Period - 15-05-2024 To 14-05-2029 | K21: 6282016827 | L21: 06282016827 | M21: cherthalaironbridge.ddrc@agilus.in | N21: Yes
A22: DDRC AGILUS PATHLABS LIMITED CHERTHALA | B22: DDRC AGILUS PATHLABS LIMITED GROUND FLOOROPP SNMM GOVT HSS CHERTHALA | C22: Alappuzha | D22: 688524 | E22: Medium | F22: DDRC AGILUS PATHLABS LIMITED CHERTHALA DDRC AGILUS PATHLABS LIMITED GROUND FLOOROPP SNMM GOVT HSS CHERTHALA Kerala, Alappuzha - 688524 | G22: Both Laboratory and Diagnostic Imaging Centre | H22: Modern Medicine | I22: Permanent | J22: P32554MM0754, Period - 24-05-2024 To 23-05-2029 | K22: 9074558956 | L22: 09074558956 | M22: cherthala.ddrc@agilus.in | N22: Yes
A23: Dial Scan Doctors Imageology and Laboratory | B23: Vandanam, Alappuzha | C23: Alappuzha | D23: 688001 | E23: Medium | F23: Dial Scan Doctors Imageology and Laboratory Vandanam Kerala, Alappuzha - 688001 | G23: Both Laboratory and Diagnostic Imaging Centre | H23: Modern Medicine | I23: Provisional | J23: T32554MM13099, Period - 27-01-2025 To 26-07-2029 | K23: 9744169000 | L23: 04772280022 | M23: ashaloui@gmail.com | N23: Yes
A24: Doctors Imageology and Laboratory | B24: 263G, Alappuzha | C24: Alappuzha | D24: 688001 | E24: Medium | F24: Doctors Imageology and Laboratory 263G Kerala, Alappuzha - 688001 | G24: Both Laboratory and Diagnostic Imaging Centre | H24: Modern Medicine | I24: Provisional | J24: T32554MM13097, Period - 27-01-2025 To 26-07-2029 | K24: 9744169000 | L24: 04772280022 | M24: ashaloui@gmail.com | N24: Yes
A25: HI TECHDIAGNOSTIC CENTRE | B25: PARAVOOR JUNCTION , PATTOLIMARKET PO , KANDALLOOR NORTH | C25: Alappuzha | D25: 690531 | E25: High | F25: HI TECHDIAGNOSTIC CENTRE PARAVOOR JUNCTION, PATTOLIMARKET PO, KANDALLOOR NORTH Kerala, Alappuzha - 690531 | G25: Both Laboratory and Diagnostic Imaging Centre | H25: Modern Medicine | I25: Provisional | J25: T32554MM1601, Period - 22-12-2023 To 21-06-2028 | K25: 9946410677 | L25: 09946410677 | M25: hitechdiagnosticcentre77@gmail.com | N25: Yes
A26: HITECH LAB & ECG DIAGNOSTIC CENTRE | B26: NEAR MARARIKULAM TEMPLE, SL PURAM P O, ALAPPUZHA | C26: Alappuzha | D26: 688001 | E26: Medium | F26: HITECH LAB & ECG DIAGNOSTIC CENTRE NEAR MARARIKULAM TEMPLE, SL PURAM P O Kerala, Alappuzha - 688001 | G26: Both Laboratory and Diagnostic Imaging Centre | H26: Modern Medicine | I26: Provisional | J26: T32554MMBOTH00017, Period - 09-11-2020 To 08-05-2025 | K26: 9526768089 | L26: 04772249231 | M26: hitechlabmkm@gmail.com | N26: Yes
A27: K R MEDICAL CLINIC PRIVATE LIMITED | B27: East Of St Mary s Bridge Cherthala | C27: Alappuzha | D27: 688524 | E27: Medium | F27: K R MEDICAL CLINIC PRIVATE LIMITED East Of St Mary s Bridge Cherthala Kerala, Alappuzha - 688524 | G27: Both Laboratory and Diagnostic Imaging Centre | H27: Modern Medicine | I27: Permanent | J27: P32554MM5816, Period - 21-01-2026 To 21-01-2031 | K27: 9020918833 | L27: 09020918833 | M27: krlabcherthala@gmail.com | N27: Yes
A28: KAYAMKULAM SCANS | B28: GLASS TOWER , CHIRAKADAVAM , KAYAMKULAM | C28: Alappuzha | D28: 690502 | E28: Medium | F28: KAYAMKULAM SCANS GLASS TOWER, CHIRAKADAVAM, KAYAMKULAM Kerala, Alappuzha - 690502 | G28: Both Laboratory and Diagnostic Imaging Centre | H28: Modern Medicine | I28: Provisional | J28: T32554MM1925, Period - 29-12-2023 To 28-06-2028 | K28: 9447789580 | L28: 09447789580 | M28: kayamkulamscans@gmail.com | N28: Yes
A29: KERALA PATHOLOGICAL LABORATORY | B29: KAILAS BUILDING , HARIPPAD | C29: Alappuzha | E29: No PIN | F29: KERALA PATHOLOGICAL LABORATORY KAILAS BUILDING, HARIPPAD Kerala, Alappuzha | G29: Both Laboratory and Diagnostic Imaging Centre | H29: Modern Medicine | I29: Provisional | J29: T32554MM4235, Period - 29-01-2024 To 28-07-2028 | K29: 9447749179 | L29: 09447749179 | M29: keralapathlab@yahoo.co.in | N29: Yes
A30: KOCHIN CLINICAL LABORATORY AND X-RAY | B30: KOCHIN CLINICAL LAB, RAIBAN COMPLEX, ALAPPUZHA | C30: Alappuzha | D30: 688001 | E30: Medium | F30: KOCHIN CLINICAL LABORATORY AND X-RAY KOCHIN CLINICAL LAB, RAIBAN COMPLEX Kerala, Alappuzha - 688001 | G30: Both Laboratory and Diagnostic Imaging Centre | H30: Modern Medicine | I30: Provisional | J30: T32554MMBOTH00012, Period - 14-02-2020 To 13-08-2024 | K30: 9946046364 | M30: akhilsatheesh86@gmail.com | N30: Yes
A31: KRISHNA DIAGNOSTIC CENTRE | B31: KRISHNA DIAGNOSTIC CENTRE OPP TALUK HOSPITAL THURAVOOR | C31: Alappuzha | D31: 688532 | E31: Medium | F31: KRISHNA DIAGNOSTIC CENTRE KRISHNA DIAGNOSTIC CENTRE OPP TALUK HOSPITAL THURAVOOR Kerala, Alappuzha - 688532 | G31: Both Laboratory and Diagnostic Imaging Centre | H31: Modern Medicine | I31: Provisional | J31: T32554MMBOTH00009, Period - 10-12-2019 To 09-06-2024 | K31: 9249740460 | L31: 04782561479 | M31: krishnalab70@gmail.com | N31: Yes
A32: MDRC SCANS AND HEALTHCARE PVT LTD | B32: OPP EMS STADIUM BEACH ROAD ALAPPUZHA | C32: Alappuzha | D32: 688001 | E32: Medium | F32: MDRC SCANS AND HEALTHCARE PVT LTD OPP EMS STADIUM BEACH ROAD Kerala, Alappuzha - 688001 | G32: Both Laboratory and Diagnostic Imaging Centre | H32: Modern Medicine | I32: Provisional | J32: T32554MM2097, Period - 01-01-2024 To 30-06-2028 | K32: 8547337460 | L32: 04772237461 | M32: mdrc.alpy@gmail.com | N32: Yes
A33: MEDIVISION SCAN AND DIAGNOSTIC RESEARCH CENTRE | B33: MEDIVISION SCAN AND DIAGNOSTIC RESERCH CENTRE PVT.LTD, NEAR GOVERNMENT HOSPITAL. MAVELIKARA | C33: Alappuzha | E33: No PIN | F33: MEDIVISION SCAN AND DIAGNOSTIC RESEARCH CENTRE MEDIVISION SCAN AND DIAGNOSTIC RESERCH CENTRE PVT.LTD, NEAR GOVERNMENT HOSPITAL. MAVELIKARA Kerala, Alappuzha | G33: Both Laboratory and Diagnostic Imaging Centre | H33: Modern Medicine | I33: Provisional | J33: T32554MM2213, Period - 05-01-2024 To 04-07-2028 | K33: 8547089595 | L33: 08547089595 | M33: medivision9595@gmail.com | N33: Yes
A34: METROPOLIS HEALTHCARE LIMITED | B34: SANKARS LAB METROPOLIS , OPPOSITE EXCISE OFFICE , NEAR GENERAL HOSPITAL, ALAPPUZHA | C34: Alappuzha | D34: 688001 | E34: Medium | F34: METROPOLIS HEALTHCARE LIMITED SANKARS LAB METROPOLIS, OPPOSITE EXCISE OFFICE, NEAR GENERAL HOSPITAL Kerala, Alappuzha - 688001 | G34: Both Laboratory and Diagnostic Imaging Centre | H34: Modern Medicine | I34: Provisional | J34: T32554MM1107, Period - 19-10-2023 To 18-04-2028 | K34: 9947711185 | L34: 04772260019 | M34: jyothilakshmi.r@metropolisindia.com | N34: Yes
A35: MIDAS SCANS & LABORATORY | B35: NIZA CENTER, GROUND FLOOR, GENERAL HOSPITAL JUNCTION, NEAR SBI, BEACH ROAD, ALAPPUZHA | C35: Alappuzha | D35: 688001 | E35: Medium | F35: MIDAS SCANS & LABORATORY NIZA CENTER, GROUND FLOOR, GENERAL HOSPITAL JUNCTION, NEAR SBI, BEACH ROAD Kerala, Alappuzha - 688001 | G35: Both Laboratory and Diagnostic Imaging Centre | H35: Modern Medicine | I35: Provisional | J35: T32554MMBOTH00010, Period - 10-12-2019 To 09-06-2024 | K35: 9447734412 | L35: 04772251952 | M35: midasscans@gmail.com | N35: Yes
A36: Medivision Scan and Diagnostic Research Centre | B36: Puthiyidom, Kayamkulam, Kerala 690502 | C36: Alappuzha | D36: 690502 | E36: High | F36: Medivision Scan and Diagnostic Research Centre Puthiyidom, Kayamkulam Kerala, Alappuzha - 690502 | G36: Both Laboratory and Diagnostic Imaging Centre | H36: Modern Medicine | I36: Provisional | J36: T32554MM4145, Period - 29-01-2024 To 28-07-2028 | K36: 8547189595 | L36: 08547189595 | M36: medkylm@gmail.com | N36: Yes
A37: Microlab Scan And Diagnostics | B37: Sree Muruga Complex, Near Thazakkara MarThoma Church | C37: Alappuzha | E37: No PIN | F37: Microlab Scan And Diagnostics Sree Muruga Complex, Near Thazakkara MarThoma Church Kerala, Alappuzha | G37: Both Laboratory and Diagnostic Imaging Centre | H37: Modern Medicine | I37: Permanent | J37: P32554MM1214, Period - 16-09-2024 To 15-09-2029 | K37: 9526417700 | L37: 00000000000 | M37: microlabmavelikkara@gmail.com | N37: Yes
A38: Microlab laboratories | B38: Vaidyan parampil buliding , Charummoodu , Chunakkara , Alappuzha | C38: Alappuzha | D38: 688001 | E38: Medium | F38: Microlab laboratories Vaidyan parampil buliding, Charummoodu, Chunakkara Kerala, Alappuzha - 688001 | G38: Both Laboratory and Diagnostic Imaging Centre | H38: Modern Medicine | I38: Permanent | J38: P32554MM2486, Period - 28-01-2025 To 27-01-2030 | K38: 8075374539 | L38: 09539359777 | M38: microlabcharummoodu@gmail.com | N38: Yes
A39: NEW DESINGANAD SCANS | B39: PUTHIYOIDOM, OPP.TRIVENI SUPER MARKET, KAYAMKULAM | C39: Alappuzha | D39: 690502 | E39: Medium | F39: NEW DESINGANAD SCANS PUTHIYOIDOM, OPP.TRIVENI SUPER MARKET, KAYAMKULAM Kerala, Alappuzha - 690502 | G39: Both Laboratory and Diagnostic Imaging Centre | H39: Modern Medicine | I39: Provisional | J39: T32554MMBOTH00014, Period - 07-03-2020 To 06-09-2024 | K39: 9496257747 | M39: newdesinganad@gmail.com | N39: Yes
A40: NEW DESINGANAD SCANS | B40: oppo.thriveni supermarket , gazel arcade , charumood po | C40: Alappuzha | E40: No PIN | F40: NEW DESINGANAD SCANS oppo.thriveni supermarket, gazel arcade, charumood po Kerala, Alappuzha | G40: Both Laboratory and Diagnostic Imaging Centre | H40: Modern Medicine | I40: Provisional | J40: T32554MM89, Period - 31-01-2023 To 30-07-2027 | K40: 9496257747 | L40: 04792444411 | M40: newdesinganad@gmail.com | N40: Yes
...

Sheet Summary
A1: Establishments by district and PIN confidence
A3: District | B3: High | C3: Medium | D3: Low | E3: No PIN | F3: Total
A4: Alappuzha | B4: =COUNTIFS('Mail List'!$C$2:$C$12307,$A4,'Mail List'!$E$2:$E$12307,B$3) -> 213 | C4: =COUNTIFS('Mail List'!$C$2:$C$12307,$A4,'Mail List'!$E$2:$E$12307,C$3) -> 352 | D4: =COUNTIFS('Mail List'!$C$2:$C$12307,$A4,'Mail List'!$E$2:$E$12307,D$3) -> 99 | E4: =COUNTIFS('Mail List'!$C$2:$C$12307,$A4,'Mail List'!$E$2:$E$12307,E$3) -> 192 | F4: =SUM(B4:E4) -> 856
A5: Ernakulam | B5: =COUNTIFS('Mail List'!$C$2:$C$12307,$A5,'Mail List'!$E$2:$E$12307,B$3) -> 428 | C5: =COUNTIFS('Mail List'!$C$2:$C$12307,$A5,'Mail List'!$E$2:$E$12307,C$3) -> 661 | D5: =COUNTIFS('Mail List'!$C$2:$C$12307,$A5,'Mail List'!$E$2:$E$12307,D$3) -> 94 | E5: =COUNTIFS('Mail List'!$C$2:$C$12307,$A5,'Mail List'!$E$2:$E$12307,E$3) -> 638 | F5: =SUM(B5:E5) -> 1821
A6: Idukki | B6: =COUNTIFS('Mail List'!$C$2:$C$12307,$A6,'Mail List'!$E$2:$E$12307,B$3) -> 91 | C6: =COUNTIFS('Mail List'!$C$2:$C$12307,$A6,'Mail List'!$E$2:$E$12307,C$3) -> 55 | D6: =COUNTIFS('Mail List'!$C$2:$C$12307,$A6,'Mail List'!$E$2:$E$12307,D$3) -> 4 | E6: =COUNTIFS('Mail List'!$C$2:$C$12307,$A6,'Mail List'!$E$2:$E$12307,E$3) -> 220 | F6: =SUM(B6:E6) -> 370
A7: Kannur | B7: =COUNTIFS('Mail List'!$C$2:$C$12307,$A7,'Mail List'!$E$2:$E$12307,B$3) -> 206 | C7: =COUNTIFS('Mail List'!$C$2:$C$12307,$A7,'Mail List'!$E$2:$E$12307,C$3) -> 410 | D7: =COUNTIFS('Mail List'!$C$2:$C$12307,$A7,'Mail List'!$E$2:$E$12307,D$3) -> 103 | E7: =COUNTIFS('Mail List'!$C$2:$C$12307,$A7,'Mail List'!$E$2:$E$12307,E$3) -> 244 | F7: =SUM(B7:E7) -> 963
A8: Kasargod | B8: =COUNTIFS('Mail List'!$C$2:$C$12307,$A8,'Mail List'!$E$2:$E$12307,B$3) -> 31 | C8: =COUNTIFS('Mail List'!$C$2:$C$12307,$A8,'Mail List'!$E$2:$E$12307,C$3) -> 126 | D8: =COUNTIFS('Mail List'!$C$2:$C$12307,$A8,'Mail List'!$E$2:$E$12307,D$3) -> 21 | E8: =COUNTIFS('Mail List'!$C$2:$C$12307,$A8,'Mail List'!$E$2:$E$12307,E$3) -> 65 | F8: =SUM(B8:E8) -> 243
A9: Kollam | B9: =COUNTIFS('Mail List'!$C$2:$C$12307,$A9,'Mail List'!$E$2:$E$12307,B$3) -> 220 | C9: =COUNTIFS('Mail List'!$C$2:$C$12307,$A9,'Mail List'!$E$2:$E$12307,C$3) -> 322 | D9: =COUNTIFS('Mail List'!$C$2:$C$12307,$A9,'Mail List'!$E$2:$E$12307,D$3) -> 85 | E9: =COUNTIFS('Mail List'!$C$2:$C$12307,$A9,'Mail List'!$E$2:$E$12307,E$3) -> 240 | F9: =SUM(B9:E9) -> 867
A10: Kottayam | B10: =COUNTIFS('Mail List'!$C$2:$C$12307,$A10,'Mail List'!$E$2:$E$12307,B$3) -> 284 | C10: =COUNTIFS('Mail List'!$C$2:$C$12307,$A10,'Mail List'!$E$2:$E$12307,C$3) -> 299 | D10: =COUNTIFS('Mail List'!$C$2:$C$12307,$A10,'Mail List'!$E$2:$E$12307,D$3) -> 84 | E10: =COUNTIFS('Mail List'!$C$2:$C$12307,$A10,'Mail List'!$E$2:$E$12307,E$3) -> 277 | F10: =SUM(B10:E10) -> 944
A11: Kozhikode | B11: =COUNTIFS('Mail List'!$C$2:$C$12307,$A11,'Mail List'!$E$2:$E$12307,B$3) -> 223 | C11: =COUNTIFS('Mail List'!$C$2:$C$12307,$A11,'Mail List'!$E$2:$E$12307,C$3) -> 264 | D11: =COUNTIFS('Mail List'!$C$2:$C$12307,$A11,'Mail List'!$E$2:$E$12307,D$3) -> 36 | E11: =COUNTIFS('Mail List'!$C$2:$C$12307,$A11,'Mail List'!$E$2:$E$12307,E$3) -> 440 | F11: =SUM(B11:E11) -> 963
A12: Malappuram | B12: =COUNTIFS('Mail List'!$C$2:$C$12307,$A12,'Mail List'!$E$2:$E$12307,B$3) -> 200 | C12: =COUNTIFS('Mail List'!$C$2:$C$12307,$A12,'Mail List'!$E$2:$E$12307,C$3) -> 382 | D12: =COUNTIFS('Mail List'!$C$2:$C$12307,$A12,'Mail List'!$E$2:$E$12307,D$3) -> 116 | E12: =COUNTIFS('Mail List'!$C$2:$C$12307,$A12,'Mail List'!$E$2:$E$12307,E$3) -> 368 | F12: =SUM(B12:E12) -> 1066
A13: Palakkad | B13: =COUNTIFS('Mail List'!$C$2:$C$12307,$A13,'Mail List'!$E$2:$E$12307,B$3) -> 65 | C13: =COUNTIFS('Mail List'!$C$2:$C$12307,$A13,'Mail List'!$E$2:$E$12307,C$3) -> 258 | D13: =COUNTIFS('Mail List'!$C$2:$C$12307,$A13,'Mail List'!$E$2:$E$12307,D$3) -> 2 | E13: =COUNTIFS('Mail List'!$C$2:$C$12307,$A13,'Mail List'!$E$2:$E$12307,E$3) -> 384 | F13: =SUM(B13:E13) -> 709
A14: Pathanamthitta | B14: =COUNTIFS('Mail List'!$C$2:$C$12307,$A14,'Mail List'!$E$2:$E$12307,B$3) -> 125 | C14: =COUNTIFS('Mail List'!$C$2:$C$12307,$A14,'Mail List'!$E$2:$E$12307,C$3) -> 174 | D14: =COUNTIFS('Mail List'!$C$2:$C$12307,$A14,'Mail List'!$E$2:$E$12307,D$3) -> 30 | E14: =COUNTIFS('Mail List'!$C$2:$C$12307,$A14,'Mail List'!$E$2:$E$12307,E$3) -> 223 | F14: =SUM(B14:E14) -> 552
A15: Thiruvananthapuram | B15: =COUNTIFS('Mail List'!$C$2:$C$12307,$A15,'Mail List'!$E$2:$E$12307,B$3) -> 333 | C15: =COUNTIFS('Mail List'!$C$2:$C$12307,$A15,'Mail List'!$E$2:$E$12307,C$3) -> 411 | D15: =COUNTIFS('Mail List'!$C$2:$C$12307,$A15,'Mail List'!$E$2:$E$12307,D$3) -> 23 | E15: =COUNTIFS('Mail List'!$C$2:$C$12307,$A15,'Mail List'!$E$2:$E$12307,E$3) -> 479 | F15: =SUM(B15:E15) -> 1246
... A17: Wayanad | B17: =COUNTIFS('Mail List'!$C$2:$C$12307,$A17,'Mail List'!$E$2:$E$12307,B$3) -> 110 | C17: =COUNTIFS('Mail List'!$C$2:$C$12307,$A17,'Mail List'!$E$2:$E$12307,C$3) -> 190 | D17: =COUNTIFS('Mail List'!$C$2:$C$12307,$A17,'Mail List'!$E$2:$E$12307,D$3) -> 2 | E17: =COUNTIFS('Mail List'!$C$2:$C$12307,$A17,'Mail List'!$E$2:$E$12307,E$3) -> 217 | F17: =SUM(B17:E17) -> 519
A18: Total | B18: =SUM(B4:B17) -> 2807 | C18: =SUM(C4:C17) -> 4371 | D18: =SUM(D4:D17) -> 850 | E18: =SUM(E4:E17) -> 4278 | F18: =SUM(F4:F17) -> 12306
A21: Establishments by category
A23: Category | B23: Count
A24: Dental | B24: =COUNTIF('Mail List'!$G$2:$G$12307,$A24) -> 4443
A25: Laboratory | B25: =COUNTIF('Mail List'!$G$2:$G$12307,$A25) -> 4308
A26: Health Centre/Clinics/Polyclinics | B26: =COUNTIF('Mail List'!$G$2:$G$12307,$A26) -> 1304
A27: Both Laboratory and Diagnostic Imaging Centre | B27: =COUNTIF('Mail List'!$G$2:$G$12307,$A27) -> 593
A28: Multi Specialty Hospital | B28: =COUNTIF('Mail List'!$G$2:$G$12307,$A28) -> 585
A29: Single Specialty Hospital | B29: =COUNTIF('Mail List'!$G$2:$G$12307,$A29) -> 542
A30: Day Care Centre | B30: =COUNTIF('Mail List'!$G$2:$G$12307,$A30) -> 214
A31: Any Other | B31: =COUNTIF('Mail List'!$G$2:$G$12307,$A31) -> 138
A32: Diagnostic Imaging Centre | B32: =COUNTIF('Mail List'!$G$2:$G$12307,$A32) -> 118
A33: Teaching Hospital | B33: =COUNTIF('Mail List'!$G$2:$G$12307,$A33) -> 43
A34: Maternity Home | B34: =COUNTIF('Mail List'!$G$2:$G$12307,$A34) -> 11
A35: Dental College | B35: =COUNTIF('Mail List'!$G$2:$G$12307,$A35) -> 6
